<?xml version="1.0" encoding="utf-8"?>
<!-- This URDF was automatically created by SolidWorks to URDF Exporter! Originally created by Stephen Brawner (brawner@gmail.com) 
     Commit Version: 1.6.0-4-g7f85cfe  Build Version: 1.6.7995.38578
     For more information, please see http://wiki.ros.org/sw_urdf_exporter -->
<robot
  name="shark_asm03">
  
  <link
    name="base_link">
    <inertial>
      <origin
        xyz="0.038191 -0.0011682 0.019734"
        rpy="0 0 0" />
      <mass
        value="1.753" />
      <inertia
        ixx="0.0011992"
        ixy="-5.9532E-07"
        ixz="-4.094E-05"
        iyy="0.0049871"
        iyz="-7.025E-07"
        izz="0.0055025" />
    </inertial>
    <visual>
      <origin
        xyz="0 0 0"
        rpy="0 0 0" />
      <geometry>
        <mesh
          filename="package://shark_asm03/meshes/base_link.STL" />
      </geometry>
      <material
        name="">
        <color
          rgba="1 1 1 1" />
      </material>
    </visual>
    <collision>
      <origin
        xyz="0 0 0"
        rpy="0 0 0" />
      <geometry>
        <mesh
          filename="package://shark_asm03/meshes/base_link.STL" />
      </geometry>
    </collision>
  </link>

  <link
    name="body_fin">
    <inertial>
      <origin
        xyz="0.00914833180910446 -0.00106620065635634 2.43483887424727E-05"
        rpy="0 0 0" />
      <mass
        value="0.0777166528344648" />
      <inertia
        ixx="3.1049811920015E-05"
        ixy="-3.79774234954185E-10"
        ixz="-3.71777530984048E-08"
        iyy="1.59640204823738E-05"
        iyz="1.84244309068481E-07"
        izz="4.63071029422297E-05" />
    </inertial>
    <visual>
      <origin
        xyz="0 0 0"
        rpy="0 0 0" />
      <geometry>
        <mesh
          filename="package://shark_asm03/meshes/body_fin.STL" />
      </geometry>
      <material
        name="">
        <color
          rgba="0.898039215686275 0.917647058823529 0.929411764705882 1" />
      </material>
    </visual>
    <collision>
      <origin
        xyz="0 0 0"
        rpy="0 0 0" />
      <geometry>
        <mesh
          filename="package://shark_asm03/meshes/body_fin.STL" />
      </geometry>
    </collision>
  </link>
  <joint
    name="body_fin_joint"
    type="revolute">
    <origin
      xyz="0 0 0"
      rpy="0 0 0" />
    <parent
      link="base_link" />
    <child
      link="body_fin" />
    <axis
      xyz="0 1 0" />
    <limit
      lower="-0.52"
      upper="0.52"
      effort="0"
      velocity="0" />
  </joint>
  <link
    name="link1">
    <inertial>
      <origin
        xyz="0.0273740098565554 1.00730841318137E-06 0.00233674443466103"
        rpy="0 0 0" />
      <mass
        value="0.276636032216536" />
      <inertia
        ixx="0.000221100847637612"
        ixy="2.2348802662522E-08"
        ixz="1.48015173973935E-06"
        iyy="0.000306819552826337"
        iyz="-1.51964922899048E-08"
        izz="0.000127523807633018" />
    </inertial>
    <visual>
      <origin
        xyz="0 0 0"
        rpy="0 0 0" />
      <geometry>
        <mesh
          filename="package://shark_asm03/meshes/link1.STL" />
      </geometry>
      <material
        name="">
        <color
          rgba="1 1 1 1" />
      </material>
    </visual>
    <collision>
      <origin
        xyz="0 0 0"
        rpy="0 0 0" />
      <geometry>
        <mesh
          filename="package://shark_asm03/meshes/link1.STL" />
      </geometry>
    </collision>
  </link>
  <joint
    name="joint1"
    type="revolute">
    <origin
      xyz="0.16952 -0.001 0.022"
      rpy="0 0 0" />
    <parent
      link="base_link" />
    <child
      link="link1" />
    <axis
      xyz="0 0 1" />
    <limit
      lower="-0.54777"
      upper="0.54777"
      effort="5.0"
      velocity="2.0" />
  </joint>
  <link
    name="link2">
    <inertial>
      <origin
        xyz="0.0314265398767537 7.62073086331302E-06 0.00321188485864419"
        rpy="0 0 0" />
      <mass
        value="0.23079291425153" />
      <inertia
        ixx="0.00014162458840055"
        ixy="1.43555615633064E-07"
        ixz="6.00764632389094E-06"
        iyy="0.000192380669161936"
        iyz="7.81445755193396E-09"
        izz="0.000124286520292589" />
    </inertial>
    <visual>
      <origin
        xyz="0 0 0"
        rpy="0 0 0" />
      <geometry>
        <mesh
          filename="package://shark_asm03/meshes/link2.STL" />
      </geometry>
      <material
        name="">
        <color
          rgba="1 1 1 1" />
      </material>
    </visual>
    <collision>
      <origin
        xyz="0 0 0"
        rpy="0 0 0" />
      <geometry>
        <mesh
          filename="package://shark_asm03/meshes/link2.STL" />
      </geometry>
    </collision>
  </link>
  <joint
    name="joint2"
    type="revolute">
    <origin
      xyz="0.06502 0 0"
      rpy="0 0 0" />
    <parent
      link="link1" />
    <child
      link="link2" />
    <axis
      xyz="0 0 -1" />
    <limit
      lower="-0.5242"
      upper="0.5242"
      effort="5.0"
      velocity="2.0" />
  </joint>
  <link
    name="link3">
    <inertial>
      <origin
        xyz="0.0326080633640175 0.000105371441976573 0.00539746824234997"
        rpy="0 0 0" />
      <mass
        value="0.194723948866163" />
      <inertia
        ixx="7.98162926930531E-05"
        ixy="-2.49207714784249E-07"
        ixz="4.9950223786246E-06"
        iyy="0.00012964160787792"
        iyz="7.02465415687571E-09"
        izz="9.38054135694122E-05" />
    </inertial>
    <visual>
      <origin
        xyz="0 0 0"
        rpy="0 0 0" />
      <geometry>
        <mesh
          filename="package://shark_asm03/meshes/link3.STL" />
      </geometry>
      <material
        name="">
        <color
          rgba="0.898039215686275 0.917647058823529 0.929411764705882 1" />
      </material>
    </visual>
    <collision>
      <origin
        xyz="0 0 0"
        rpy="0 0 0" />
      <geometry>
        <mesh
          filename="package://shark_asm03/meshes/link3.STL" />
      </geometry>
    </collision>
  </link>
  <joint
    name="joint3"
    type="revolute">
    <origin
      xyz="0.06402 0 0"
      rpy="0 0 0" />
    <parent
      link="link2" />
    <child
      link="link3" />
    <axis
      xyz="0 0 1" />
    <limit
      lower="-0.424"
      upper="0.424"
      effort="4.0"
      velocity="1.5" />
  </joint>
  <link
    name="link4">
    <inertial>
      <origin
        xyz="0.0437179055651961 -6.72418090937084E-06 0.0104856415382952"
        rpy="0 0 0" />
      <mass
        value="0.111699348341862" />
      <inertia
        ixx="0.000186665766811727"
        ixy="1.66443330076751E-10"
        ixz="-3.18917008238277E-05"
        iyy="0.000232685091219534"
        iyz="-2.78353657152308E-08"
        izz="5.59758373965963E-05" />
    </inertial>
    <visual>
      <origin
        xyz="0 0 0"
        rpy="0 0 0" />
      <geometry>
        <mesh
          filename="package://shark_asm03/meshes/link4.STL" />
      </geometry>
      <material
        name="">
        <color
          rgba="1 1 1 1" />
      </material>
    </visual>
    <collision>
      <origin
        xyz="0 0 0"
        rpy="0 0 0" />
      <geometry>
        <mesh
          filename="package://shark_asm03/meshes/link4.STL" />
      </geometry>
    </collision>
  </link>
  <joint
    name="joint4"
    type="revolute">
    <origin
      xyz="0.0668 0 0"
      rpy="0 0 0" />
    <parent
      link="link3" />
    <child
      link="link4" />
    <axis
      xyz="0 0 -1" />
    <limit
      lower="-0.265"
      upper="0.265"
      effort="2.0"
      velocity="1.0" />
  </joint>  

</robot>
