<?xml version="1.0"?>
<robot xmlns:xacro="http://www.ros.org/wiki/xacro">

  <!--                                                                      -->
  <!-- MACRO FOR THRUSTER UNITS  -->
  <!--                                                                      -->

  <!-- Provide the propeller mesh in a separate file with the rotation axis
  over propeller's frame X-axis in DAE (Collada) or STL format.
  -->
  <!-- <xacro:property name="prop_mesh_file" value="file://$(find shark_description)/meshes/propeller.dae"/> -->

  <!--
    Thruster macro with integration of joint and link. The thrusters should
    be initialized in the actuators.xacro file.
  -->
  <!-- <xacro:macro name="thruster_macro" params="robot_namespace thruster_id *origin"> -->

    <!--
    Dummy link as place holder for the thruster frame,
    since thrusters can often be inside the collision geometry
    of the vehicle and may cause internal collisions if set otherwise
    -->
    <!-- <link name="${robot_namespace}/thruster_${thruster_id}">

      <visual>
        <geometry>
          <mesh filename="${prop_mesh_file}" scale="1 1 1" />
        </geometry>
      </visual>

      <inertial>
        <mass value="0.001" />
        <origin xyz="0 0 0" rpy="0 0 0"/>
        <inertia ixx="0.000000017" ixy="0.0" ixz="0.0"
               iyy="0.000000017" iyz="0.0"
               izz="0.000000017" />
      </inertial>
    </link> -->

    <!-- Joint between thruster link and vehicle base link -->
    <!-- <joint name="${robot_namespace}/thruster_${thruster_id}_joint" type="continuous">
      <xacro:insert_block name="origin" />
      <axis xyz="1 0 0" />
      <parent link="${robot_namespace}/base_link" />
      <child link="${robot_namespace}/thruster_${thruster_id}" />
    </joint> -->

    


  <!--                                                                      -->
  <!-- MACRO FOR FIN/RUDDER UNITS  -->
  <!--                                                                      -->

  <!--
    This macro can be used to add fins to the body of the vehicle, the fins
    should be initialized in the actuators.xacro file. If you vehicle has no
    fins, you can erase the macro below.
  -->

  <!-- A separate mesh for the fin should be stored in the meshes folder -->
  <!-- <xacro:property name="fin_mesh_file" value="file://$(find shark_description)/meshes/fin.dae"/> -->

  <!-- Fin joint limits  -->
  <!-- <xacro:property name="fin_min_joint_limit" value="${0.0 * d2r}"/>
  <xacro:property name="fin_max_joint_limit" value="${0.0 * d2r}"/> -->

  <xacro:macro name="fin_macro" params="namespace fin_id parent_link:=${namespace}/base_link axis lower_limit upper_limit effort velocity *origin fin_mesh_file mass">
      <joint name="${namespace}/fin${fin_id}_joint" type="revolute">
          <limit effort="${effort}" lower="${lower_limit}" upper="${upper_limit}" velocity="${velocity}"/>
          <xacro:insert_block name="origin"/>
          <axis xyz="${axis}"/>
          <parent link="${parent_link}" />
          <child link="${namespace}/fin${fin_id}" />
      </joint>

      <link name="${namespace}/fin${fin_id}">
        <inertial>
          <mass value="${mass}" />
          <origin xyz="0 0 0" rpy="0 0 0"/>
          <inertia ixx="0.001" ixy="0.0" ixz="0.0"
                 iyy="0.001" iyz="0.0"
                 izz="0.001" />  <!-- 增大转动惯量，提升物理稳定性 -->
        </inertial>
        <visual>
          <origin xyz="0 0 0" rpy="0 0 0" />
          <geometry>
            <mesh filename="${fin_mesh_file}" scale="1 1 1"/>
          </geometry>
        </visual>
      </link>

      <gazebo>
        <plugin name="${namespace}_fin${fin_id}_model" filename="libuuv_fin_ros_plugin.so">
          <fin_id>${fin_id}</fin_id>
          <command_topic>${namespace}/fins/${fin_id}/input</command_topic>
          <!--
            First order dynamics model for the fin joint dynamics,
            replace an appropriate time constant
          -->
          <dynamics>
            <type>FirstOrder</type>
            <timeConstant>0.1</timeConstant>
          </dynamics>

          <!--
            Definition of the lift and drag model, choose ONE of the models
            below according to the model you want to use.
          -->

          <!--
            1) References for the two line lift and drag model:
              [1] https://en.wikipedia.org/wiki/Lift_coefficient
              [2] http://gazebosim.org/tutorials?tut=aerodynamics&cat=plugins
          -->
          <!-- <liftdrag>
            <type>TwoLines</type>
            <area>${replace here the value for the area of the fin's cross section}</area>
            <fluid_density>0.0</fluid_density>
            <a0>0.0</a0>
            <alpha_stall>0.0</alpha_stall>
            <cla>0.0</cla> -->
                <!-- ^= 0.244 when using deg -->
            <!-- <cla_stall>0.0</cla_stall>
            <cda>0.0</cda>
            <cda_stall>0.0</cda_stall>
          </liftdrag> -->

          <!--
            2) Reference for the quadratic lift and drag model:
              [1] Engelhardtsen, Oystein. 3D AUV Collision Avoidance.
                  MS thesis. Institutt for teknisk kybernetikk, 2007.
                  https://brage.bibsys.no/xmlui/handle/11250/259834
          -->
          <liftdrag>
            <type>Quadratic</type>
            <lift_constant>0.0</lift_constant>
            <drag_constant>0.0</drag_constant>
          </liftdrag>

          <!--
            Further parameters necessary for the lift and drag plugin
          -->

          <!-- Current velocity topic -->
          <current_velocity_topic>/hydrodynamics/current_velocity</current_velocity_topic>

          <!-- Name of the correspodent fin link and joint  -->
          <link_name>${namespace}/fin${fin_id}</link_name>
          <joint_name>${namespace}/fin${fin_id}_joint</joint_name>

          <!-- Output topic to publish the current angle of the fin joint -->
          <output_topic>${namespace}/fins/${fin_id}/output</output_topic>
          
          <wrench_topic>${namespace}/fins/${fin_id}/wrench_topic</wrench_topic>
        </plugin>
      </gazebo>
  </xacro:macro>

</robot>
